Workbook

Sheet Dashboard Executive
A1: PHARMACEUTICAL EVENTS OPERATIONS | EXECUTIVE DASHBOARD | FY 2025
A2: Generated: 24 June 2026 | Confidential – For Internal Use Only
A4: KEY PERFORMANCE INDICATORS
A5: TOTAL BUDGET | C5: TOTAL COMMITTED | E5: TOTAL ACTUAL | G5: CURRENT FORECAST | I5: SAVINGS / UNDERSPEND | K5: VARIANCE % | M5: TOTAL EVENTS | O5: ACTIVE EVENTS | Q5: COMPLETED
A6: =SUM('Budget Planning'!$J$2:$J$51) | C6: =SUM('Budget Planning'!$N$2:$N$51) | E6: =SUM('Budget Planning'!$O$2:$O$51) | G6: =SUM('Budget Planning'!$M$2:$M$51) | I6: =A6-G6 | K6: =IF(A6=0,0,I6/A6) | M6: =COUNTA('Event Master Database'!$A$2:$A$51) | O6: =COUNTIF('Event Master Database'!$L$2:$L$51,"Confirmed")+COUNTIF('Event Master Database'!$L$2:$L$51,"In Progress")+COUNTIF('Event Master Database'!$L$2:$L$51,"Planning") | Q6: =COUNTIF('Event Master Database'!$L$2:$L$51,"Completed")
A7: CANCELLED | C7: ON HOLD | E7: HIGH RISK SUPS | G7: OVERDUE INVOICES | I7: TOTAL POs | K7: FORECAST ACCURACY | M7: TOTAL SUPPLIERS | O7: AVG EVENT BUDGET | Q7: BUDGET UTILIZATION
A8: =COUNTIF('Event Master Database'!$L$2:$L$51,"Cancelled") | C8: =COUNTIF('Event Master Database'!$L$2:$L$51,"On Hold") | E8: =COUNTIF('Supplier Management'!$M$2:$M$149,"High") | G8: =COUNTIF('PO Tracking'!$N$2:$N$149,"Overdue") | I8: =COUNTA('PO Tracking'!$A$2:$A$149) | K8: =1-ABS(K6) | M8: =SUMPRODUCT(1/COUNTIF('Supplier Management'!$D$2:$D$149,'Supplier Management'!$D$2:$D$149)) | O8: =IF(M6=0,0,A6/M6) | Q8: =IF(A6=0,0,C6/A6)
A10: MONTHLY BUDGET VS FORECAST TREND (2025) | J10: BUDGET BY THERAPEUTIC AREA
A11: Month | B11: Budget (€) | C11: Forecast (€) | D11: Actual (€) | E11: Variance (€) | F11: Var % | G11: Events | H11: Status | J11: Therapeutic Area | K11: Budget (€) | L11: Committed (€) | M11: Utilization % | N11: Events
A12: Jan | B12: =SUMPRODUCT((MONTH('Budget Planning'!$H$2:$H$51)=1)*(YEAR('Budget Planning'!$H$2:$H$51)=2025)*'Budget Planning'!$J$2:$J$51) | C12: =SUMPRODUCT((MONTH('Budget Planning'!$H$2:$H$51)=1)*(YEAR('Budget Planning'!$H$2:$H$51)=2025)*'Budget Planning'!$M$2:$M$51) | D12: =SUMPRODUCT((MONTH('Budget Planning'!$H$2:$H$51)=1)*(YEAR('Budget Planning'!$H$2:$H$51)=2025)*'Budget Planning'!$O$2:$O$51) | E12: =B12-C12 | F12: =IF(B12=0,0,E12/B12) | G12: =SUMPRODUCT((MONTH('Budget Planning'!$H$2:$H$51)=1)*(YEAR('Budget Planning'!$H$2:$H$51)=2025)*1) | H12: =IF(F12<-0.05,"At Risk","On Track") | J12: Immunology | K12: =SUMIF('Budget Planning'!$E$2:$E$51,$J12,'Budget Planning'!$J$2:$J$51) | L12: =SUMIF('Budget Planning'!$E$2:$E$51,$J12,'Budget Planning'!$N$2:$N$51) | M12: =IF(K12=0,0,L12/K12) | N12: =COUNTIF('Budget Planning'!$E$2:$E$51,$J12)
A13: Feb | B13: =SUMPRODUCT((MONTH('Budget Planning'!$H$2:$H$51)=2)*(YEAR('Budget Planning'!$H$2:$H$51)=2025)*'Budget Planning'!$J$2:$J$51) | C13: =SUMPRODUCT((MONTH('Budget Planning'!$H$2:$H$51)=2)*(YEAR('Budget Planning'!$H$2:$H$51)=2025)*'Budget Planning'!$M$2:$M$51) | D13: =SUMPRODUCT((MONTH('Budget Planning'!$H$2:$H$51)=2)*(YEAR('Budget Planning'!$H$2:$H$51)=2025)*'Budget Planning'!$O$2:$O$51) | E13: =B13-C13 | F13: =IF(B13=0,0,E13/B13) | G13: =SUMPRODUCT((MONTH('Budget Planning'!$H$2:$H$51)=2)*(YEAR('Budget Planning'!$H$2:$H$51)=2025)*1) | H13: =IF(F13<-0.05,"At Risk","On Track") | J13: Neurology | K13: =SUMIF('Budget Planning'!$E$2:$E$51,$J13,'Budget Planning'!$J$2:$J$51) | L13: =SUMIF('Budget Planning'!$E$2:$E$51,$J13,'Budget Planning'!$N$2:$N$51) | M13: =IF(K13=0,0,L13/K13) | N13: =COUNTIF('Budget Planning'!$E$2:$E$51,$J13)
A14: Mar | B14: =SUMPRODUCT((MONTH('Budget Planning'!$H$2:$H$51)=3)*(YEAR('Budget Planning'!$H$2:$H$51)=2025)*'Budget Planning'!$J$2:$J$51) | C14: =SUMPRODUCT((MONTH('Budget Planning'!$H$2:$H$51)=3)*(YEAR('Budget Planning'!$H$2:$H$51)=2025)*'Budget Planning'!$M$2:$M$51) | D14: =SUMPRODUCT((MONTH('Budget Planning'!$H$2:$H$51)=3)*(YEAR('Budget Planning'!$H$2:$H$51)=2025)*'Budget Planning'!$O$2:$O$51) | E14: =B14-C14 | F14: =IF(B14=0,0,E14/B14) | G14: =SUMPRODUCT((MONTH('Budget Planning'!$H$2:$H$51)=3)*(YEAR('Budget Planning'!$H$2:$H$51)=2025)*1) | H14: =IF(F14<-0.05,"At Risk","On Track") | J14: Rare Diseases | K14: =SUMIF('Budget Planning'!$E$2:$E$51,$J14,'Budget Planning'!$J$2:$J$51) | L14: =SUMIF('Budget Planning'!$E$2:$E$51,$J14,'Budget Planning'!$N$2:$N$51) | M14: =IF(K14=0,0,L14/K14) | N14: =COUNTIF('Budget Planning'!$E$2:$E$51,$J14)
A15: Apr | B15: =SUMPRODUCT((MONTH('Budget Planning'!$H$2:$H$51)=4)*(YEAR('Budget Planning'!$H$2:$H$51)=2025)*'Budget Planning'!$J$2:$J$51) | C15: =SUMPRODUCT((MONTH('Budget Planning'!$H$2:$H$51)=4)*(YEAR('Budget Planning'!$H$2:$H$51)=2025)*'Budget Planning'!$M$2:$M$51) | D15: =SUMPRODUCT((MONTH('Budget Planning'!$H$2:$H$51)=4)*(YEAR('Budget Planning'!$H$2:$H$51)=2025)*'Budget Planning'!$O$2:$O$51) | E15: =B15-C15 | F15: =IF(B15=0,0,E15/B15) | G15: =SUMPRODUCT((MONTH('Budget Planning'!$H$2:$H$51)=4)*(YEAR('Budget Planning'!$H$2:$H$51)=2025)*1) | H15: =IF(F15<-0.05,"At Risk","On Track") | J15: Cardiology | K15: =SUMIF('Budget Planning'!$E$2:$E$51,$J15,'Budget Planning'!$J$2:$J$51) | L15: =SUMIF('Budget Planning'!$E$2:$E$51,$J15,'Budget Planning'!$N$2:$N$51) | M15: =IF(K15=0,0,L15/K15) | N15: =COUNTIF('Budget Planning'!$E$2:$E$51,$J15)
A16: May | B16: =SUMPRODUCT((MONTH('Budget Planning'!$H$2:$H$51)=5)*(YEAR('Budget Planning'!$H$2:$H$51)=2025)*'Budget Planning'!$J$2:$J$51) | C16: =SUMPRODUCT((MONTH('Budget Planning'!$H$2:$H$51)=5)*(YEAR('Budget Planning'!$H$2:$H$51)=2025)*'Budget Planning'!$M$2:$M$51) | D16: =SUMPRODUCT((MONTH('Budget Planning'!$H$2:$H$51)=5)*(YEAR('Budget Planning'!$H$2:$H$51)=2025)*'Budget Planning'!$O$2:$O$51) | E16: =B16-C16 | F16: =IF(B16=0,0,E16/B16) | G16: =SUMPRODUCT((MONTH('Budget Planning'!$H$2:$H$51)=5)*(YEAR('Budget Planning'!$H$2:$H$51)=2025)*1) | H16: =IF(F16<-0.05,"At Risk","On Track") | J16: Oncology | K16: =SUMIF('Budget Planning'!$E$2:$E$51,$J16,'Budget Planning'!$J$2:$J$51) | L16: =SUMIF('Budget Planning'!$E$2:$E$51,$J16,'Budget Planning'!$N$2:$N$51) | M16: =IF(K16=0,0,L16/K16) | N16: =COUNTIF('Budget Planning'!$E$2:$E$51,$J16)
A17: Jun | B17: =SUMPRODUCT((MONTH('Budget Planning'!$H$2:$H$51)=6)*(YEAR('Budget Planning'!$H$2:$H$51)=2025)*'Budget Planning'!$J$2:$J$51) | C17: =SUMPRODUCT((MONTH('Budget Planning'!$H$2:$H$51)=6)*(YEAR('Budget Planning'!$H$2:$H$51)=2025)*'Budget Planning'!$M$2:$M$51) | D17: =SUMPRODUCT((MONTH('Budget Planning'!$H$2:$H$51)=6)*(YEAR('Budget Planning'!$H$2:$H$51)=2025)*'Budget Planning'!$O$2:$O$51) | E17: =B17-C17 | F17: =IF(B17=0,0,E17/B17) | G17: =SUMPRODUCT((MONTH('Budget Planning'!$H$2:$H$51)=6)*(YEAR('Budget Planning'!$H$2:$H$51)=2025)*1) | H17: =IF(F17<-0.05,"At Risk","On Track") | J17: Infectious Diseases | K17: =SUMIF('Budget Planning'!$E$2:$E$51,$J17,'Budget Planning'!$J$2:$J$51) | L17: =SUMIF('Budget Planning'!$E$2:$E$51,$J17,'Budget Planning'!$N$2:$N$51) | M17: =IF(K17=0,0,L17/K17) | N17: =COUNTIF('Budget Planning'!$E$2:$E$51,$J17)
A18: Jul | B18: =SUMPRODUCT((MONTH('Budget Planning'!$H$2:$H$51)=7)*(YEAR('Budget Planning'!$H$2:$H$51)=2025)*'Budget Planning'!$J$2:$J$51) | C18: =SUMPRODUCT((MONTH('Budget Planning'!$H$2:$H$51)=7)*(YEAR('Budget Planning'!$H$2:$H$51)=2025)*'Budget Planning'!$M$2:$M$51) | D18: =SUMPRODUCT((MONTH('Budget Planning'!$H$2:$H$51)=7)*(YEAR('Budget Planning'!$H$2:$H$51)=2025)*'Budget Planning'!$O$2:$O$51) | E18: =B18-C18 | F18: =IF(B18=0,0,E18/B18) | G18: =SUMPRODUCT((MONTH('Budget Planning'!$H$2:$H$51)=7)*(YEAR('Budget Planning'!$H$2:$H$51)=2025)*1) | H18: =IF(F18<-0.05,"At Risk","On Track") | J18: Hematology | K18: =SUMIF('Budget Planning'!$E$2:$E$51,$J18,'Budget Planning'!$J$2:$J$51) | L18: =SUMIF('Budget Planning'!$E$2:$E$51,$J18,'Budget Planning'!$N$2:$N$51) | M18: =IF(K18=0,0,L18/K18) | N18: =COUNTIF('Budget Planning'!$E$2:$E$51,$J18)
A19: Aug | B19: =SUMPRODUCT((MONTH('Budget Planning'!$H$2:$H$51)=8)*(YEAR('Budget Planning'!$H$2:$H$51)=2025)*'Budget Planning'!$J$2:$J$51) | C19: =SUMPRODUCT((MONTH('Budget Planning'!$H$2:$H$51)=8)*(YEAR('Budget Planning'!$H$2:$H$51)=2025)*'Budget Planning'!$M$2:$M$51) | D19: =SUMPRODUCT((MONTH('Budget Planning'!$H$2:$H$51)=8)*(YEAR('Budget Planning'!$H$2:$H$51)=2025)*'Budget Planning'!$O$2:$O$51) | E19: =B19-C19 | F19: =IF(B19=0,0,E19/B19) | G19: =SUMPRODUCT((MONTH('Budget Planning'!$H$2:$H$51)=8)*(YEAR('Budget Planning'!$H$2:$H$51)=2025)*1) | H19: =IF(F19<-0.05,"At Risk","On Track") | J19: Gastroenterology | K19: =SUMIF('Budget Planning'!$E$2:$E$51,$J19,'Budget Planning'!$J$2:$J$51) | L19: =SUMIF('Budget Planning'!$E$2:$E$51,$J19,'Budget Planning'!$N$2:$N$51) | M19: =IF(K19=0,0,L19/K19) | N19: =COUNTIF('Budget Planning'!$E$2:$E$51,$J19)
A20: Sep | B20: =SUMPRODUCT((MONTH('Budget Planning'!$H$2:$H$51)=9)*(YEAR('Budget Planning'!$H$2:$H$51)=2025)*'Budget Planning'!$J$2:$J$51) | C20: =SUMPRODUCT((MONTH('Budget Planning'!$H$2:$H$51)=9)*(YEAR('Budget Planning'!$H$2:$H$51)=2025)*'Budget Planning'!$M$2:$M$51) | D20: =SUMPRODUCT((MONTH('Budget Planning'!$H$2:$H$51)=9)*(YEAR('Budget Planning'!$H$2:$H$51)=2025)*'Budget Planning'!$O$2:$O$51) | E20: =B20-C20 | F20: =IF(B20=0,0,E20/B20) | G20: =SUMPRODUCT((MONTH('Budget Planning'!$H$2:$H$51)=9)*(YEAR('Budget Planning'!$H$2:$H$51)=2025)*1) | H20: =IF(F20<-0.05,"At Risk","On Track")
A21: Oct | B21: =SUMPRODUCT((MONTH('Budget Planning'!$H$2:$H$51)=10)*(YEAR('Budget Planning'!$H$2:$H$51)=2025)*'Budget Planning'!$J$2:$J$51) | C21: =SUMPRODUCT((MONTH('Budget Planning'!$H$2:$H$51)=10)*(YEAR('Budget Planning'!$H$2:$H$51)=2025)*'Budget Planning'!$M$2:$M$51) | D21: =SUMPRODUCT((MONTH('Budget Planning'!$H$2:$H$51)=10)*(YEAR('Budget Planning'!$H$2:$H$51)=2025)*'Budget Planning'!$O$2:$O$51) | E21: =B21-C21 | F21: =IF(B21=0,0,E21/B21) | G21: =SUMPRODUCT((MONTH('Budget Planning'!$H$2:$H$51)=10)*(YEAR('Budget Planning'!$H$2:$H$51)=2025)*1) | H21: =IF(F21<-0.05,"At Risk","On Track")
A22: Nov | B22: =SUMPRODUCT((MONTH('Budget Planning'!$H$2:$H$51)=11)*(YEAR('Budget Planning'!$H$2:$H$51)=2025)*'Budget Planning'!$J$2:$J$51) | C22: =SUMPRODUCT((MONTH('Budget Planning'!$H$2:$H$51)=11)*(YEAR('Budget Planning'!$H$2:$H$51)=2025)*'Budget Planning'!$M$2:$M$51) | D22: =SUMPRODUCT((MONTH('Budget Planning'!$H$2:$H$51)=11)*(YEAR('Budget Planning'!$H$2:$H$51)=2025)*'Budget Planning'!$O$2:$O$51) | E22: =B22-C22 | F22: =IF(B22=0,0,E22/B22) | G22: =SUMPRODUCT((MONTH('Budget Planning'!$H$2:$H$51)=11)*(YEAR('Budget Planning'!$H$2:$H$51)=2025)*1) | H22: =IF(F22<-0.05,"At Risk","On Track")
A23: Dec | B23: =SUMPRODUCT((MONTH('Budget Planning'!$H$2:$H$51)=12)*(YEAR('Budget Planning'!$H$2:$H$51)=2025)*'Budget Planning'!$J$2:$J$51) | C23: =SUMPRODUCT((MONTH('Budget Planning'!$H$2:$H$51)=12)*(YEAR('Budget Planning'!$H$2:$H$51)=2025)*'Budget Planning'!$M$2:$M$51) | D23: =SUMPRODUCT((MONTH('Budget Planning'!$H$2:$H$51)=12)*(YEAR('Budget Planning'!$H$2:$H$51)=2025)*'Budget Planning'!$O$2:$O$51) | E23: =B23-C23 | F23: =IF(B23=0,0,E23/B23) | G23: =SUMPRODUCT((MONTH('Budget Planning'!$H$2:$H$51)=12)*(YEAR('Budget Planning'!$H$2:$H$51)=2025)*1) | H23: =IF(F23<-0.05,"At Risk","On Track")
A26: EVENT STATUS DISTRIBUTION | J26: TOP 8 SUPPLIERS BY COMMITTED SPEND
A27: Status | B27: Count | C27: % of Total | D27: Budget (€) | E27: Avg Budget (€) | J27: Supplier | K27: Category | L27: Committed (€) | M27: Share % | N27: Risk
A28: Completed | B28: =COUNTIF('Event Master Database'!$L$2:$L$51,$A28) | C28: =IF(SUM($B$28:$B$34)=0,0,B28/SUM($B$28:$B$34)) | D28: =SUMPRODUCT(('Event Master Database'!$L$2:$L$51=$A28)*'Budget Planning'!$J$2:$J$51) | E28: =IF(B28=0,0,D28/B28) | J28: TechEvent Systems | K28: Registration & Tech | L28: =SUMIF('Supplier Management'!$D$2:$D$149,$J28,'Supplier Management'!$I$2:$I$149) | M28: =IF(SUM('Supplier Management'!$I$2:$I$149)=0,0,L28/SUM('Supplier Management'!$I$2:$I$149)) | N28: High
A29: Confirmed | B29: =COUNTIF('Event Master Database'!$L$2:$L$51,$A29) | C29: =IF(SUM($B$28:$B$34)=0,0,B29/SUM($B$28:$B$34)) | D29: =SUMPRODUCT(('Event Master Database'!$L$2:$L$51=$A29)*'Budget Planning'!$J$2:$J$51) | E29: =IF(B29=0,0,D29/B29) | J29: Translingua Pro | K29: Translation & Interpretation | L29: =SUMIF('Supplier Management'!$D$2:$D$149,$J29,'Supplier Management'!$I$2:$I$149) | M29: =IF(SUM('Supplier Management'!$I$2:$I$149)=0,0,L29/SUM('Supplier Management'!$I$2:$I$149)) | N29: High
A30: Cancelled | B30: =COUNTIF('Event Master Database'!$L$2:$L$51,$A30) | C30: =IF(SUM($B$28:$B$34)=0,0,B30/SUM($B$28:$B$34)) | D30: =SUMPRODUCT(('Event Master Database'!$L$2:$L$51=$A30)*'Budget Planning'!$J$2:$J$51) | E30: =IF(B30=0,0,D30/B30) | J30: InterCongress PCO | K30: PCO / Event Agency | L30: =SUMIF('Supplier Management'!$D$2:$D$149,$J30,'Supplier Management'!$I$2:$I$149) | M30: =IF(SUM('Supplier Management'!$I$2:$I$149)=0,0,L30/SUM('Supplier Management'!$I$2:$I$149)) | N30: Medium
A31: In Progress | B31: =COUNTIF('Event Master Database'!$L$2:$L$51,$A31) | C31: =IF(SUM($B$28:$B$34)=0,0,B31/SUM($B$28:$B$34)) | D31: =SUMPRODUCT(('Event Master Database'!$L$2:$L$51=$A31)*'Budget Planning'!$J$2:$J$51) | E31: =IF(B31=0,0,D31/B31) | J31: AVIAWORLD Travel | K31: Travel & Air | L31: =SUMIF('Supplier Management'!$D$2:$D$149,$J31,'Supplier Management'!$I$2:$I$149) | M31: =IF(SUM('Supplier Management'!$I$2:$I$149)=0,0,L31/SUM('Supplier Management'!$I$2:$I$149)) | N31: High
A32: Planning | B32: =COUNTIF('Event Master Database'!$L$2:$L$51,$A32) | C32: =IF(SUM($B$28:$B$34)=0,0,B32/SUM($B$28:$B$34)) | D32: =SUMPRODUCT(('Event Master Database'!$L$2:$L$51=$A32)*'Budget Planning'!$J$2:$J$51) | E32: =IF(B32=0,0,D32/B32) | J32: Catering Excellence | K32: F&B / Catering | L32: =SUMIF('Supplier Management'!$D$2:$D$149,$J32,'Supplier Management'!$I$2:$I$149) | M32: =IF(SUM('Supplier Management'!$I$2:$I$149)=0,0,L32/SUM('Supplier Management'!$I$2:$I$149)) | N32: High
A33: Closed | B33: =COUNTIF('Event Master Database'!$L$2:$L$51,$A33) | C33: =IF(SUM($B$28:$B$34)=0,0,B33/SUM($B$28:$B$34)) | D33: =SUMPRODUCT(('Event Master Database'!$L$2:$L$51=$A33)*'Budget Planning'!$J$2:$J$51) | E33: =IF(B33=0,0,D33/B33) | J33: PharmaLogix | K33: Logistics & Transport | L33: =SUMIF('Supplier Management'!$D$2:$D$149,$J33,'Supplier Management'!$I$2:$I$149) | M33: =IF(SUM('Supplier Management'!$I$2:$I$149)=0,0,L33/SUM('Supplier Management'!$I$2:$I$149)) | N33: Medium
A34: On Hold | B34: =COUNTIF('Event Master Database'!$L$2:$L$51,$A34) | C34: =IF(SUM($B$28:$B$34)=0,0,B34/SUM($B$28:$B$34)) | D34: =SUMPRODUCT(('Event Master Database'!$L$2:$L$51=$A34)*'Budget Planning'!$J$2:$J$51) | E34: =IF(B34=0,0,D34/B34) | J34: HealthMarketing Group | K34: Marketing Agency | L34: =SUMIF('Supplier Management'!$D$2:$D$149,$J34,'Supplier Management'!$I$2:$I$149) | M34: =IF(SUM('Supplier Management'!$I$2:$I$149)=0,0,L34/SUM('Supplier Management'!$I$2:$I$149)) | N34: High
J35: Venue Masters EMEA | K35: Venue Sourcing | L35: =SUMIF('Supplier Management'!$D$2:$D$149,$J35,'Supplier Management'!$I$2:$I$149) | M35: =IF(SUM('Supplier Management'!$I$2:$I$149)=0,0,L35/SUM('Supplier Management'!$I$2:$I$149)) | N35: High

Sheet Event Master Database
A1: Event ID | B1: Event Name | C1: Therapeutic Area | D1: Product | E1: Business Unit | F1: Event Type | G1: Start Date | H1: End Date | I1: Duration (Days) | J1: City | K1: Country | L1: Status | M1: Responsible Owner | N1: Cost Center | O1: GL Account | P1: Created Date | Q1: Last Modified | R1: Notes
A2: EVT-2025-001 | B2: Cordavex Internal Meeting Vienna Apr 2025 | C2: Cardiology | D2: Cordavex | E2: BU Cardiovascular | F2: Internal Meeting | G2: 45772 | H2: 45773 | I2: 2 | J2: Vienna | K2: Austria | L2: Completed | M2: Maria Kowalski | N2: CC-1500 | O2: GL-6311 | P2: 45665 | Q2: 45685
A3: EVT-2025-002 | B3: Eplitazan Investigator Meeting Barcelona Jan 2025 | C3: Cardiology | D3: Eplitazan | E3: BU Cardiovascular | F3: Investigator Meeting | G3: 45673 | H3: 45674 | I3: 2 | J3: Barcelona | K3: Spain | L3: Confirmed | M3: Lena Schneider | N3: CC-8308 | O3: GL-6311 | P3: 45502 | Q3: 45522
A4: EVT-2025-003 | B4: Influximab Webinar Athens Apr 2025 | C4: Immunology | D4: Influximab | E4: BU Immunology | F4: Webinar | G4: 45770 | H4: 45772 | I4: 3 | J4: Athens | K4: Greece | L4: Completed | M4: Ana García | N4: CC-6730 | O4: GL-6312 | P4: 45690 | Q4: 45703
A5: EVT-2025-004 | B5: Cognivex Investigator Meeting Stockholm May 2025 | C5: Neurology | D5: Cognivex | E5: BU Neuroscience | F5: Investigator Meeting | G5: 45800 | H5: 45802 | I5: 3 | J5: Stockholm | K5: Sweden | L5: Confirmed | M5: Lucas Dupont | N5: CC-2480 | O5: GL-6312 | P5: 45737 | Q5: 45754
A6: EVT-2025-005 | B6: Hemaflex Launch Event Brussels Nov 2025 | C6: Hematology | D6: Hemaflex | E6: BU Oncology | F6: Launch Event | G6: 45967 | H6: 45969 | I6: 3 | J6: Brussels | K6: Belgium | L6: Cancelled | M6: Thomas Dubois | N6: CC-1813 | O6: GL-6311 | P6: 45798 | Q6: 45821
A7: EVT-2025-006 | B7: Miotrex Advisory Board Istanbul May 2025 | C7: Cardiology | D7: Miotrex | E7: BU Cardiovascular | F7: Advisory Board | G7: 45808 | H7: 45810 | I7: 3 | J7: Istanbul | K7: Turkey | L7: Completed | M7: Thomas Dubois | N7: CC-4511 | O7: GL-6311 | P7: 45666 | Q7: 45678
A8: EVT-2025-007 | B8: Bioflair Advisory Board Vienna Feb 2025 | C8: Immunology | D8: Bioflair | E8: BU Immunology | F8: Advisory Board | G8: 45709 | H8: 45711 | I8: 3 | J8: Vienna | K8: Austria | L8: In Progress | M8: Maria Kowalski | N8: CC-4387 | O8: GL-6312 | P8: 45566 | Q8: 45584
A9: EVT-2025-008 | B9: Axotrin Launch Event Amsterdam Dec 2025 | C9: Neurology | D9: Axotrin | E9: BU Neuroscience | F9: Launch Event | G9: 46001 | H9: 46003 | I9: 3 | J9: Amsterdam | K9: Netherlands | L9: Completed | M9: Maria Kowalski | N9: CC-9409 | O9: GL-6310 | P9: 45831 | Q9: 45860
A10: EVT-2025-009 | B10: Cognivex KOL Meeting Milan Aug 2025 | C10: Neurology | D10: Cognivex | E10: BU Neuroscience | F10: KOL Meeting | G10: 45894 | H10: 45896 | I10: 3 | J10: Milan | K10: Italy | L10: Confirmed | M10: Maria Kowalski | N10: CC-1145 | O10: GL-6315 | P10: 45718 | Q10: 45727
A11: EVT-2025-010 | B11: Influximab Launch Event Barcelona Apr 2025 | C11: Immunology | D11: Influximab | E11: BU Immunology | F11: Launch Event | G11: 45775 | H11: 45776 | I11: 2 | J11: Barcelona | K11: Spain | L11: Cancelled | M11: Emma Johansson | N11: CC-3837 | O11: GL-6320 | P11: 45613 | Q11: 45618
A12: EVT-2025-011 | B12: Influximab Launch Event Amsterdam Dec 2025 | C12: Immunology | D12: Influximab | E12: BU Immunology | F12: Launch Event | G12: 45993 | H12: 45995 | I12: 3 | J12: Amsterdam | K12: Netherlands | L12: Completed | M12: Maria Kowalski | N12: CC-4666 | O12: GL-6312 | P12: 45856 | Q12: 45886
A13: EVT-2025-012 | B13: Rarzolene KOL Meeting Istanbul Oct 2025 | C13: Rare Diseases | D13: Rarzolene | E13: BU Rare Diseases | F13: KOL Meeting | G13: 45933 | H13: 45935 | I13: 3 | J13: Istanbul | K13: Turkey | L13: Completed | M13: Emma Johansson | N13: CC-6004 | O13: GL-6312 | P13: 45819 | Q13: 45836
... A51: EVT-2025-050 | B51: Infectoban Launch Event Paris Jun 2025 | C51: Infectious Diseases | D51: Infectoban | E51: BU Infectious Diseases | F51: Launch Event | G51: 45811 | H51: 45813 | I51: 3 | J51: Paris | K51: France | L51: Completed | M51: Lucas Dupont | N51: CC-9745 | O51: GL-6311 | P51: 45658 | Q51: 45674

Sheet Budget Planning
A1: Event ID | B1: Event Name | C1: Cost Center | D1: GL Account | E1: Therapeutic Area | F1: Business Unit | G1: Event Type | H1: Start Date | I1: Initial Budget (€) | J1: Approved Budget (€) | K1: Forecast V1 (€) | L1: Forecast V2 (€) | M1: Current Forecast (€) | N1: Committed (€) | O1: Actual Spend (€) | P1: Remaining Budget (€) | Q1: Budget Variance (€) | R1: Variance % | S1: Forecast Version | T1: Budget Status | U1: Approval Date | V1: Approved By
A2: EVT-2025-001 | B2: Cordavex Internal Meeting Vienna Apr 2025 | C2: CC-3851 | D2: GL-6320 | E2: Cardiology | F2: BU Cardiovascular | G2: Internal Meeting | H2: 45772 | I2: 374223.86 | J2: 358929.72 | K2: 345551.97 | L2: 351166.88 | M2: =L2 | N2: 324184.5 | O2: 292801.94 | P2: =M2-N2 | Q2: =J2-M2 | R2: =IF(J2=0,0,Q2/J2) | S2: FV3 | T2: On Track | U2: 45723 | V2: Thomas Dubois
A3: EVT-2025-002 | B3: Eplitazan Investigator Meeting Barcelona Jan 2025 | C3: CC-4443 | D3: GL-6315 | E3: Cardiology | F3: BU Cardiovascular | G3: Investigator Meeting | H3: 45673 | I3: 306979.08 | J3: 311221.85 | K3: 308298.7 | L3: 327323.74 | M3: =L3 | N3: 208421.34 | O3: 0 | P3: =M3-N3 | Q3: =J3-M3 | R3: =IF(J3=0,0,Q3/J3) | S3: FV1 | T3: At Risk | U3: 45555 | V3: Maria Kowalski
A4: EVT-2025-003 | B4: Influximab Webinar Athens Apr 2025 | C4: CC-9375 | D4: GL-6315 | E4: Immunology | F4: BU Immunology | G4: Webinar | H4: 45770 | I4: 383021.57 | J4: 404911.93 | K4: 409230.78 | L4: 411460.03 | M4: =L4 | N4: 287529.79 | O4: 259549.74 | P4: =M4-N4 | Q4: =J4-M4 | R4: =IF(J4=0,0,Q4/J4) | S4: FV3 | T4: On Track | U4: 45660 | V4: David O'Brien
A5: EVT-2025-004 | B5: Cognivex Investigator Meeting Stockholm May 2025 | C5: CC-5649 | D5: GL-6320 | E5: Neurology | F5: BU Neuroscience | G5: Investigator Meeting | H5: 45800 | I5: 64571.98 | J5: 68365.4 | K5: 71509.06 | L5: 75152.86 | M5: =L5 | N5: 59857.96 | O5: 0 | P5: =M5-N5 | Q5: =J5-M5 | R5: =IF(J5=0,0,Q5/J5) | S5: FV1 | T5: At Risk | U5: 45732 | V5: Emma Johansson
A6: EVT-2025-005 | B6: Hemaflex Launch Event Brussels Nov 2025 | C6: CC-4848 | D6: GL-6325 | E6: Hematology | F6: BU Oncology | G6: Launch Event | H6: 45967 | I6: 237821.07 | J6: 245614.65 | K6: 248543.87 | L6: 243640.74 | M6: =L6 | N6: 226196.03 | O6: 0 | P6: =M6-N6 | Q6: =J6-M6 | R6: =IF(J6=0,0,Q6/J6) | S6: FV2 | T6: On Track | U6: 45853 | V6: Ana García
A7: EVT-2025-006 | B7: Miotrex Advisory Board Istanbul May 2025 | C7: CC-2193 | D7: GL-6315 | E7: Cardiology | F7: BU Cardiovascular | G7: Advisory Board | H7: 45808 | I7: 48734.25 | J7: 46886.44 | K7: 48323.8 | L7: 47657.36 | M7: =L7 | N7: 24819.77 | O7: 24700.16 | P7: =M7-N7 | Q7: =J7-M7 | R7: =IF(J7=0,0,Q7/J7) | S7: FV1 | T7: On Track | U7: 45694 | V7: Ana García
A8: EVT-2025-007 | B8: Bioflair Advisory Board Vienna Feb 2025 | C8: CC-4997 | D8: GL-6311 | E8: Immunology | F8: BU Immunology | G8: Advisory Board | H8: 45709 | I8: 419543.56 | J8: 412364.42 | K8: 417715.48 | L8: 414118.06 | M8: =L8 | N8: 336826.82 | O8: 285734.62 | P8: =M8-N8 | Q8: =J8-M8 | R8: =IF(J8=0,0,Q8/J8) | S8: FV3 | T8: On Track | U8: 45645 | V8: Lena Schneider
A9: EVT-2025-008 | B9: Axotrin Launch Event Amsterdam Dec 2025 | C9: CC-7965 | D9: GL-6311 | E9: Neurology | F9: BU Neuroscience | G9: Launch Event | H9: 46001 | I9: 329297.16 | J9: 339575.05 | K9: 322784.59 | L9: 339765.03 | M9: =L9 | N9: 287618.16 | O9: 210529.64 | P9: =M9-N9 | Q9: =J9-M9 | R9: =IF(J9=0,0,Q9/J9) | S9: FV3 | T9: On Track | U9: 45894 | V9: Sophie Müller
A10: EVT-2025-009 | B10: Cognivex KOL Meeting Milan Aug 2025 | C10: CC-5082 | D10: GL-6330 | E10: Neurology | F10: BU Neuroscience | G10: KOL Meeting | H10: 45894 | I10: 348758.55 | J10: 326151.09 | K10: 341087.7 | L10: 350288.66 | M10: =L10 | N10: 183060.25 | O10: 0 | P10: =M10-N10 | Q10: =J10-M10 | R10: =IF(J10=0,0,Q10/J10) | S10: FV3 | T10: At Risk | U10: 45847 | V10: Maria Kowalski
A11: EVT-2025-010 | B11: Influximab Launch Event Barcelona Apr 2025 | C11: CC-6198 | D11: GL-6330 | E11: Immunology | F11: BU Immunology | G11: Launch Event | H11: 45775 | I11: 144854.32 | J11: 133884.75 | K11: 128975.72 | L11: 131698.49 | M11: =L11 | N11: 97326.42 | O11: 0 | P11: =M11-N11 | Q11: =J11-M11 | R11: =IF(J11=0,0,Q11/J11) | S11: FV2 | T11: On Track | U11: 45732 | V11: James Wilson
A12: EVT-2025-011 | B12: Influximab Launch Event Amsterdam Dec 2025 | C12: CC-9976 | D12: GL-6315 | E12: Immunology | F12: BU Immunology | G12: Launch Event | H12: 45993 | I12: 237543.15 | J12: 256139.26 | K12: 259024.73 | L12: 271748.06 | M12: =L12 | N12: 197601.65 | O12: 187557.71 | P12: =M12-N12 | Q12: =J12-M12 | R12: =IF(J12=0,0,Q12/J12) | S12: FV3 | T12: At Risk | U12: 45884 | V12: Marco Bianchi
A13: EVT-2025-012 | B13: Rarzolene KOL Meeting Istanbul Oct 2025 | C13: CC-5543 | D13: GL-6330 | E13: Rare Diseases | F13: BU Rare Diseases | G13: KOL Meeting | H13: 45933 | I13: 450444.1 | J13: 486228.11 | K13: 498075.32 | L13: 509139.66 | M13: =L13 | N13: 313953.94 | O13: 243054.32 | P13: =M13-N13 | Q13: =J13-M13 | R13: =IF(J13=0,0,Q13/J13) | S13: FV1 | T13: On Track | U13: 45867 | V13: Emma Johansson
... A51: EVT-2025-050 | B51: Infectoban Launch Event Paris Jun 2025 | C51: CC-8381 | D51: GL-6325 | E51: Infectious Diseases | F51: BU Infectious Diseases | G51: Launch Event | H51: 45811 | I51: 210164.19 | J51: 216907.44 | K51: 209468.75 | L51: 207189.62 | M51: =L51 | N51: 110593.51 | O51: 77504.23 | P51: =M51-N51 | Q51: =J51-M51 | R51: =IF(J51=0,0,Q51/J51) | S51: FV2 | T51: On Track | U51: 45747 | V51: James Wilson
A53: TOTALS | I53: =SUM(I2:I51) | J53: =SUM(J2:J51) | K53: =SUM(K2:K51) | L53: =SUM(L2:L51) | M53: =SUM(M2:M51) | N53: =SUM(N2:N51) | O53: =SUM(O2:O51) | P53: =SUM(P2:P51) | Q53: =SUM(Q2:Q51)

Sheet Supplier Management
A1: Record ID | B1: Event ID | C1: Event Name | D1: Supplier Name | E1: Category | F1: Contract Status | G1: PO Number | H1: Invoice Number | I1: Amount (€) | J1: Currency | K1: Payment Status | L1: Due Date | M1: Risk Indicator | N1: Payment Terms (Days) | O1: Overdue Days | P1: Notes | Q1: Last Updated
A2: SUP-0001 | B2: EVT-2025-001 | C2: Cordavex Internal Meeting Vienna Apr 2025 | D2: Translingua Pro | E2: Translation & Interpretation | F2: Contract Sent | G2: PO-2025-1001 | H2: INV-01001 | I2: 56833.03 | J2: EUR | K2: Approved | L2: 45751 | M2: Low | N2: 90 | O2: 0 | Q2: 46175
A3: SUP-0002 | B3: EVT-2025-001 | C3: Cordavex Internal Meeting Vienna Apr 2025 | D3: Catering Excellence | E3: F&B / Catering | F3: Signed | G3: PO-2025-1002 | H3: INV-01002 | I3: 50754.52 | J3: EUR | K3: Approved | L3: 45744 | M3: Medium | N3: 90 | O3: 0 | Q3: 46172
A4: SUP-0003 | B4: EVT-2025-001 | C4: Cordavex Internal Meeting Vienna Apr 2025 | D4: AVIAWORLD Travel | E4: Travel & Air | F4: Negotiating | G4: PO-2025-1003 | I4: 19535.14 | J4: EUR | K4: Cancelled | L4: 45761 | M4: High | N4: 90 | O4: 0 | Q4: 46177
A5: SUP-0004 | B5: EVT-2025-001 | C5: Cordavex Internal Meeting Vienna Apr 2025 | D5: Prime Hospitality Group | E5: Hotel & Venue | F5: Active | G5: PO-2025-1004 | I5: 14941.98 | J5: EUR | K5: Cancelled | L5: 45756 | M5: Low | N5: 45 | O5: 0 | Q5: 46194
A6: SUP-0005 | B6: EVT-2025-001 | C6: Cordavex Internal Meeting Vienna Apr 2025 | D6: TechEvent Systems | E6: Registration & Tech | F6: Signed | G6: PO-2025-1005 | H6: INV-01005 | I6: 36253.97 | J6: EUR | K6: Disputed | L6: 45751 | M6: Medium | N6: 45 | O6: 0 | Q6: 46175
A7: SUP-0006 | B7: EVT-2025-002 | C7: Eplitazan Investigator Meeting Barcelona Jan 2025 | D7: PrintMed Solutions | E7: Print & Production | F7: Contract Sent | G7: PO-2025-1006 | H7: INV-01006 | I7: 48646.86 | J7: EUR | K7: Overdue | L7: 45653 | M7: Medium | N7: 30 | O7: 544 | Q7: 46167
A8: SUP-0007 | B8: EVT-2025-002 | C8: Eplitazan Investigator Meeting Barcelona Jan 2025 | D8: HealthMarketing Group | E8: Marketing Agency | F8: Active | G8: PO-2025-1007 | I8: 19856.1 | J8: EUR | K8: Overdue | L8: 45645 | M8: Medium | N8: 45 | O8: 552 | Q8: 46194
A9: SUP-0008 | B9: EVT-2025-002 | C9: Eplitazan Investigator Meeting Barcelona Jan 2025 | D9: Translingua Pro | E9: Translation & Interpretation | F9: RFP Sent | G9: PO-2025-1008 | H9: INV-01008 | I9: 79966.65 | J9: EUR | K9: Overdue | L9: 45645 | M9: Medium | N9: 90 | O9: 552 | Q9: 46168
A10: SUP-0009 | B10: EVT-2025-003 | C10: Influximab Webinar Athens Apr 2025 | D10: Translingua Pro | E10: Translation & Interpretation | F10: Closed | G10: PO-2025-1009 | H10: INV-01009 | I10: 73453.68 | J10: EUR | K10: Paid | L10: 45758 | M10: High | N10: 90 | O10: 0 | Q10: 46172
A11: SUP-0010 | B11: EVT-2025-003 | C11: Influximab Webinar Athens Apr 2025 | D11: PrintMed Solutions | E11: Print & Production | F11: Contract Sent | G11: PO-2025-1010 | H11: INV-01010 | I11: 77586.31 | J11: EUR | K11: Invoiced | L11: 45748 | M11: Low | N11: 90 | O11: 0 | Q11: 46192
A12: SUP-0011 | B12: EVT-2025-004 | C12: Cognivex Investigator Meeting Stockholm May 2025 | D12: TechEvent Systems | E12: Registration & Tech | F12: Terminated | G12: PO-2025-1011 | I12: 34108.32 | J12: EUR | K12: Paid | L12: 45778 | M12: Low | N12: 90 | O12: 0 | Q12: 46173
A13: SUP-0012 | B13: EVT-2025-005 | C13: Hemaflex Launch Event Brussels Nov 2025 | D13: AVIAWORLD Travel | E13: Travel & Air | F13: RFP Sent | G13: PO-2025-1012 | H13: INV-01012 | I13: 77674.41 | J13: EUR | K13: Cancelled | L13: 45948 | M13: Medium | N13: 60 | O13: 0 | Q13: 46178
A14: SUP-0013 | B14: EVT-2025-005 | C14: Hemaflex Launch Event Brussels Nov 2025 | D14: Translingua Pro | E14: Translation & Interpretation | F14: Contract Sent | G14: PO-2025-1013 | H14: INV-01013 | I14: 44322.3 | J14: EUR | K14: Overdue | L14: 45947 | M14: Low | N14: 30 | O14: 250 | Q14: 46170
A15: SUP-0014 | B15: EVT-2025-005 | C15: Hemaflex Launch Event Brussels Nov 2025 | D15: InterCongress PCO | E15: PCO / Event Agency | F15: Contract Sent | G15: PO-2025-1014 | H15: INV-01014 | I15: 40882.46 | J15: EUR | K15: Approved | L15: 45946 | M15: Medium | N15: 45 | O15: 0 | Q15: 46182
A16: SUP-0015 | B16: EVT-2025-005 | C16: Hemaflex Launch Event Brussels Nov 2025 | D16: PharmaLogix | E16: Logistics & Transport | F16: RFP Sent | G16: PO-2025-1015 | H16: INV-01015 | I16: 74358.48 | J16: EUR | K16: Paid | L16: 45946 | M16: Medium | N16: 90 | O16: 0 | Q16: 46194
A17: SUP-0016 | B17: EVT-2025-005 | C17: Hemaflex Launch Event Brussels Nov 2025 | D17: Catering Excellence | E17: F&B / Catering | F17: Active | G17: PO-2025-1016 | I17: 51141.74 | J17: EUR | K17: Invoiced | L17: 45953 | M17: Medium | N17: 90 | O17: 0 | Q17: 46183
A18: SUP-0017 | B18: EVT-2025-006 | C18: Miotrex Advisory Board Istanbul May 2025 | D18: PrintMed Solutions | E18: Print & Production | F18: Closed | G18: PO-2025-1017 | H18: INV-01017 | I18: 19526.65 | J18: EUR | K18: Pending | L18: 45798 | M18: Low | N18: 30 | O18: 0 | Q18: 46195
A19: SUP-0018 | B19: EVT-2025-007 | C19: Bioflair Advisory Board Vienna Feb 2025 | D19: Translingua Pro | E19: Translation & Interpretation | F19: Negotiating | G19: PO-2025-1018 | I19: 57022.11 | J19: EUR | K19: Paid | L19: 45689 | M19: Medium | N19: 60 | O19: 0 | Q19: 46177
A20: SUP-0019 | B20: EVT-2025-007 | C20: Bioflair Advisory Board Vienna Feb 2025 | D20: KOL Connect | E20: Speaker Management | F20: Closed | G20: PO-2025-1019 | H20: INV-01019 | I20: 13282.07 | J20: EUR | K20: Overdue | L20: 45696 | M20: High | N20: 60 | O20: 501 | Q20: 46197
A21: SUP-0020 | B21: EVT-2025-008 | C21: Axotrin Launch Event Amsterdam Dec 2025 | D21: TechEvent Systems | E21: Registration & Tech | F21: Active | G21: PO-2025-1020 | I21: 63620.48 | J21: EUR | K21: Cancelled | L21: 45981 | M21: Low | N21: 45 | O21: 0 | Q21: 46167
A22: SUP-0021 | B22: EVT-2025-008 | C22: Axotrin Launch Event Amsterdam Dec 2025 | D22: InterCongress PCO | E22: PCO / Event Agency | F22: Active | G22: PO-2025-1021 | I22: 2200.09 | J22: EUR | K22: Overdue | L22: 45971 | M22: Low | N22: 60 | O22: 226 | Q22: 46181
A23: SUP-0022 | B23: EVT-2025-009 | C23: Cognivex KOL Meeting Milan Aug 2025 | D23: TechEvent Systems | E23: Registration & Tech | F23: Terminated | G23: PO-2025-1022 | H23: INV-01022 | I23: 27930.32 | J23: EUR | K23: Invoiced | L23: 45870 | M23: Low | N23: 30 | O23: 0 | Q23: 46184
A24: SUP-0023 | B24: EVT-2025-009 | C24: Cognivex KOL Meeting Milan Aug 2025 | D24: MedAudio AV Solutions | E24: AV & Technology | F24: Terminated | G24: PO-2025-1023 | I24: 56404.88 | J24: EUR | K24: Cancelled | L24: 45869 | M24: Low | N24: 45 | O24: 0 | Q24: 46182
A25: SUP-0024 | B25: EVT-2025-009 | C25: Cognivex KOL Meeting Milan Aug 2025 | D25: Translingua Pro | E25: Translation & Interpretation | F25: Signed | G25: PO-2025-1024 | H25: INV-01024 | I25: 26817.75 | J25: EUR | K25: Cancelled | L25: 45872 | M25: Medium | N25: 60 | O25: 0 | Q25: 46176
A26: SUP-0025 | B26: EVT-2025-009 | C26: Cognivex KOL Meeting Milan Aug 2025 | D26: PrintMed Solutions | E26: Print & Production | F26: RFP Sent | G26: PO-2025-1025 | H26: INV-01025 | I26: 53767.73 | J26: EUR | K26: Paid | L26: 45867 | M26: High | N26: 90 | O26: 0 | Q26: 46193
A27: SUP-0026 | B27: EVT-2025-010 | C27: Influximab Launch Event Barcelona Apr 2025 | D27: PrintMed Solutions | E27: Print & Production | F27: RFP Sent | G27: PO-2025-1026 | H27: INV-01026 | I27: 9828.44 | J27: EUR | K27: Paid | L27: 45754 | M27: Low | N27: 30 | O27: 0 | Q27: 46197
A28: SUP-0027 | B28: EVT-2025-010 | C28: Influximab Launch Event Barcelona Apr 2025 | D28: DigitalPharma Studio | E28: Digital & Web | F28: Signed | G28: PO-2025-1027 | H28: INV-01027 | I28: 33978.33 | J28: EUR | K28: Pending | L28: 45748 | M28: High | N28: 45 | O28: 0 | Q28: 46181
A29: SUP-0028 | B29: EVT-2025-011 | C29: Influximab Launch Event Amsterdam Dec 2025 | D29: PharmaLogix | E29: Logistics & Transport | F29: Active | G29: PO-2025-1028 | H29: INV-01028 | I29: 8264.6 | J29: EUR | K29: Cancelled | L29: 45976 | M29: Medium | N29: 90 | O29: 0 | Q29: 46170
A30: SUP-0029 | B30: EVT-2025-011 | C30: Influximab Launch Event Amsterdam Dec 2025 | D30: DigitalPharma Studio | E30: Digital & Web | F30: Terminated | G30: PO-2025-1029 | H30: INV-01029 | I30: 26699.57 | J30: EUR | K30: Paid | L30: 45964 | M30: Medium | N30: 90 | O30: 0 | Q30: 46170
A31: SUP-0030 | B31: EVT-2025-011 | C31: Influximab Launch Event Amsterdam Dec 2025 | D31: KOL Connect | E31: Speaker Management | F31: Negotiating | G31: PO-2025-1030 | H31: INV-01030 | I31: 50161.84 | J31: EUR | K31: Invoiced | L31: 45979 | M31: Medium | N31: 45 | O31: 0 | Q31: 46195
A32: SUP-0031 | B32: EVT-2025-012 | C32: Rarzolene KOL Meeting Istanbul Oct 2025 | D32: MedComm Agency | E32: Medical Communication | F32: Negotiating | G32: PO-2025-1031 | H32: INV-01031 | I32: 61308.84 | J32: EUR | K32: Paid | L32: 45904 | M32: Medium | N32: 90 | O32: 0 | Q32: 46187
A33: SUP-0032 | B33: EVT-2025-013 | C33: Thrombovex KOL Meeting Berlin Sep 2025 | D33: HealthMarketing Group | E33: Marketing Agency | F33: Negotiating | G33: PO-2025-1032 | H33: INV-01032 | I33: 6377.3 | J33: EUR | K33: Approved | L33: 45900 | M33: Low | N33: 45 | O33: 0 | Q33: 46187
A34: SUP-0033 | B34: EVT-2025-013 | C34: Thrombovex KOL Meeting Berlin Sep 2025 | D34: AVIAWORLD Travel | E34: Travel & Air | F34: Active | G34: PO-2025-1033 | H34: INV-01033 | I34: 46142.39 | J34: EUR | K34: Pending | L34: 45906 | M34: Low | N34: 60 | O34: 0 | Q34: 46196
A35: SUP-0034 | B35: EVT-2025-013 | C35: Thrombovex KOL Meeting Berlin Sep 2025 | D35: TechEvent Systems | E35: Registration & Tech | F35: Negotiating | G35: PO-2025-1034 | H35: INV-01034 | I35: 50337.41 | J35: EUR | K35: Overdue | L35: 45904 | M35: Low | N35: 45 | O35: 293 | Q35: 46180
A36: SUP-0035 | B36: EVT-2025-014 | C36: Cognivex Speaker Program Athens Nov 2025 | D36: Translingua Pro | E36: Translation & Interpretation | F36: Contract Sent | G36: PO-2025-1035 | I36: 21915.48 | J36: EUR | K36: Paid | L36: 45956 | M36: Medium | N36: 90 | O36: 0 | Q36: 46185
A37: SUP-0036 | B37: EVT-2025-014 | C37: Cognivex Speaker Program Athens Nov 2025 | D37: Compliance Expert Ltd | E37: Compliance & Legal | F37: Contract Sent | G37: PO-2025-1036 | H37: INV-01036 | I37: 14322.1 | J37: EUR | K37: Overdue | L37: 45942 | M37: High | N37: 45 | O37: 255 | Q37: 46195
A38: SUP-0037 | B38: EVT-2025-015 | C38: Orphavex Congress Paris Dec 2025 | D38: KOL Connect | E38: Speaker Management | F38: Active | G38: PO-2025-1037 | I38: 32006.07 | J38: EUR | K38: Paid | L38: 45985 | M38: Low | N38: 90 | O38: 0 | Q38: 46183
A39: SUP-0038 | B39: EVT-2025-015 | C39: Orphavex Congress Paris Dec 2025 | D39: Catering Excellence | E39: F&B / Catering | F39: Closed | G39: PO-2025-1038 | H39: INV-01038 | I39: 25078.05 | J39: EUR | K39: Cancelled | L39: 45978 | M39: Low | N39: 90 | O39: 0 | Q39: 46195
A40: SUP-0039 | B40: EVT-2025-015 | C40: Orphavex Congress Paris Dec 2025 | D40: Translingua Pro | E40: Translation & Interpretation | F40: Active | G40: PO-2025-1039 | H40: INV-01039 | I40: 2631.64 | J40: EUR | K40: Pending | L40: 45979 | M40: Medium | N40: 90 | O40: 0 | Q40: 46183
...

Sheet Cost Control
A1: Record ID | B1: Event ID | C1: Event Name | D1: Therapeutic Area | E1: Business Unit | F1: Cost Category | G1: Month | H1: Quarter | I1: Budgeted (€) | J1: Committed (€) | K1: Actual (€) | L1: Variance (€) | M1: Variance % | N1: Absorption % | O1: Over/Under | P1: Status
A2: CC-00001 | B2: EVT-2025-001 | C2: Cordavex Internal Meeting Vienna Apr 2025 | D2: Cardiology | E2: BU Cardiovascular | F2: Airfare | G2: Apr-2025 | H2: Q2 2025 | I2: 35116.69 | J2: 25963.35 | K2: 25655.84 | L2: =I2-J2 | M2: =IF(I2=0,0,ROUND((I2-J2)/I2,4)) | N2: =IF(I2=0,0,J2/I2) | O2: =IF(L2>=0,"Under","Over") | P2: =IF(M2<-0.05,"Watch","On Track")
A3: CC-00002 | B3: EVT-2025-001 | C3: Cordavex Internal Meeting Vienna Apr 2025 | D3: Cardiology | E3: BU Cardiovascular | F3: Hotel | G3: Apr-2025 | H3: Q2 2025 | I3: 63210.04 | J3: 38745.02 | K3: 29284.04 | L3: =I3-J3 | M3: =IF(I3=0,0,ROUND((I3-J3)/I3,4)) | N3: =IF(I3=0,0,J3/I3) | O3: =IF(L3>=0,"Under","Over") | P3: =IF(M3<-0.05,"Watch","On Track")
A4: CC-00003 | B4: EVT-2025-001 | C4: Cordavex Internal Meeting Vienna Apr 2025 | D4: Cardiology | E4: BU Cardiovascular | F4: Venue | G4: Apr-2025 | H4: Q2 2025 | I4: 52675.03 | J4: 45241.14 | K4: 44067.71 | L4: =I4-J4 | M4: =IF(I4=0,0,ROUND((I4-J4)/I4,4)) | N4: =IF(I4=0,0,J4/I4) | O4: =IF(L4>=0,"Under","Over") | P4: =IF(M4<-0.05,"Watch","On Track")
A5: CC-00004 | B5: EVT-2025-001 | C5: Cordavex Internal Meeting Vienna Apr 2025 | D5: Cardiology | E5: BU Cardiovascular | F5: F&B | G5: Apr-2025 | H5: Q2 2025 | I5: 42140.03 | J5: 27765.24 | K5: 25890.79 | L5: =I5-J5 | M5: =IF(I5=0,0,ROUND((I5-J5)/I5,4)) | N5: =IF(I5=0,0,J5/I5) | O5: =IF(L5>=0,"Under","Over") | P5: =IF(M5<-0.05,"Watch","On Track")
A6: CC-00005 | B6: EVT-2025-001 | C6: Cordavex Internal Meeting Vienna Apr 2025 | D6: Cardiology | E6: BU Cardiovascular | F6: Logistics | G6: Apr-2025 | H6: Q2 2025 | I6: 21070.01 | J6: 20059.05 | K6: 15332.56 | L6: =I6-J6 | M6: =IF(I6=0,0,ROUND((I6-J6)/I6,4)) | N6: =IF(I6=0,0,J6/I6) | O6: =IF(L6>=0,"Under","Over") | P6: =IF(M6<-0.05,"Watch","On Track")
A7: CC-00006 | B7: EVT-2025-001 | C7: Cordavex Internal Meeting Vienna Apr 2025 | D7: Cardiology | E7: BU Cardiovascular | F7: AV & Technology | G7: Apr-2025 | H7: Q2 2025 | I7: 28093.35 | J7: 25450.85 | K7: 23114.31 | L7: =I7-J7 | M7: =IF(I7=0,0,ROUND((I7-J7)/I7,4)) | N7: =IF(I7=0,0,J7/I7) | O7: =IF(L7>=0,"Under","Over") | P7: =IF(M7<-0.05,"Watch","On Track")
A8: CC-00007 | B8: EVT-2025-001 | C8: Cordavex Internal Meeting Vienna Apr 2025 | D8: Cardiology | E8: BU Cardiovascular | F8: Agency Fees | G8: Apr-2025 | H8: Q2 2025 | I8: 49163.36 | J8: 54045.99 | K8: 41077.84 | L8: =I8-J8 | M8: =IF(I8=0,0,ROUND((I8-J8)/I8,4)) | N8: =IF(I8=0,0,J8/I8) | O8: =IF(L8>=0,"Under","Over") | P8: =IF(M8<-0.05,"Watch","On Track")
A9: CC-00008 | B9: EVT-2025-001 | C9: Cordavex Internal Meeting Vienna Apr 2025 | D9: Cardiology | E9: BU Cardiovascular | F9: Speaker Fees | G9: Apr-2025 | H9: Q2 2025 | I9: 35116.69 | J9: 23453.18 | K9: 16938.25 | L9: =I9-J9 | M9: =IF(I9=0,0,ROUND((I9-J9)/I9,4)) | N9: =IF(I9=0,0,J9/I9) | O9: =IF(L9>=0,"Under","Over") | P9: =IF(M9<-0.05,"Watch","On Track")
A10: CC-00009 | B10: EVT-2025-001 | C10: Cordavex Internal Meeting Vienna Apr 2025 | D10: Cardiology | E10: BU Cardiovascular | F10: Translation | G10: Apr-2025 | H10: Q2 2025 | I10: 10535.01 | J10: 7230.47 | K10: 6608.73 | L10: =I10-J10 | M10: =IF(I10=0,0,ROUND((I10-J10)/I10,4)) | N10: =IF(I10=0,0,J10/I10) | O10: =IF(L10>=0,"Under","Over") | P10: =IF(M10<-0.05,"Watch","On Track")
A11: CC-00010 | B11: EVT-2025-001 | C11: Cordavex Internal Meeting Vienna Apr 2025 | D11: Cardiology | E11: BU Cardiovascular | F11: Print & Production | G11: Apr-2025 | H11: Q2 2025 | I11: 7023.34 | J11: 7716.06 | K11: 7277.43 | L11: =I11-J11 | M11: =IF(I11=0,0,ROUND((I11-J11)/I11,4)) | N11: =IF(I11=0,0,J11/I11) | O11: =IF(L11>=0,"Under","Over") | P11: =IF(M11<-0.05,"Watch","On Track")
A12: CC-00011 | B12: EVT-2025-001 | C12: Cordavex Internal Meeting Vienna Apr 2025 | D12: Cardiology | E12: BU Cardiovascular | F12: Miscellaneous | G12: Apr-2025 | H12: Q2 2025 | I12: 7023.34 | J12: 7611.76 | K12: 7581.1 | L12: =I12-J12 | M12: =IF(I12=0,0,ROUND((I12-J12)/I12,4)) | N12: =IF(I12=0,0,J12/I12) | O12: =IF(L12>=0,"Under","Over") | P12: =IF(M12<-0.05,"Watch","On Track")
A13: CC-00012 | B13: EVT-2025-002 | C13: Eplitazan Investigator Meeting Barcelona Jan 2025 | D13: Cardiology | E13: BU Cardiovascular | F13: Airfare | G13: Jan-2025 | H13: Q1 2025 | I13: 32732.37 | J13: 30569.41 | K13: 0 | L13: =I13-J13 | M13: =IF(I13=0,0,ROUND((I13-J13)/I13,4)) | N13: =IF(I13=0,0,J13/I13) | O13: =IF(L13>=0,"Under","Over") | P13: =IF(M13<-0.05,"Watch","On Track")
... A551: CC-00550 | B551: EVT-2025-050 | C551: Infectoban Launch Event Paris Jun 2025 | D551: Infectious Diseases | E551: BU Infectious Diseases | F551: Miscellaneous | G551: Jun-2025 | H551: Q2 2025 | I551: 4143.79 | J551: 3839.37 | K551: 3158.8 | L551: =I551-J551 | M551: =IF(I551=0,0,ROUND((I551-J551)/I551,4)) | N551: =IF(I551=0,0,J551/I551) | O551: =IF(L551>=0,"Under","Over") | P551: =IF(M551<-0.05,"Watch","On Track")
A553: TOTALS | I553: =SUM(I2:I551) | J553: =SUM(J2:J551) | K553: =SUM(K2:K551) | L553: =SUM(L2:L551)

Sheet PO Tracking
A1: PO Number | B1: Event ID | C1: Supplier | D1: Category | E1: Request Date | F1: Approval Date | G1: Days to Approve | H1: Amount (€) | I1: Currency | J1: Cost Center | K1: GL Account | L1: PO Status | M1: Invoice Number | N1: Payment Status | O1: Due Date | P1: Days Overdue | Q1: Requestor | R1: Approver | S1: Notes
A2: PO-2025-1001 | B2: EVT-2025-001 | C2: Translingua Pro | D2: Translation & Interpretation | E2: 45690 | F2: 45699 | G2: =F2-E2 | H2: 56833.03 | I2: EUR | J2: CC-8272 | K2: GL-6315 | L2: Pending Approval | M2: INV-01001 | N2: Approved | O2: 45751 | P2: 0 | Q2: Marco Bianchi | R2: David O'Brien
A3: PO-2025-1002 | B3: EVT-2025-001 | C3: Catering Excellence | D3: F&B / Catering | E3: 45713 | F3: 45719 | G3: =F3-E3 | H3: 50754.52 | I3: EUR | J3: CC-5785 | K3: GL-6310 | L3: Approved | M3: INV-01002 | N3: Approved | O3: 45744 | P3: 0 | Q3: James Wilson | R3: Lena Schneider
A4: PO-2025-1003 | B4: EVT-2025-001 | C4: AVIAWORLD Travel | D4: Travel & Air | E4: 45713 | F4: 45718 | G4: =F4-E4 | H4: 19535.14 | I4: EUR | J4: CC-8492 | K4: GL-6320 | L4: Cancelled | N4: Cancelled | O4: 45761 | P4: 0 | Q4: Carlos Navarro | R4: Lena Schneider
A5: PO-2025-1004 | B5: EVT-2025-001 | C5: Prime Hospitality Group | D5: Hotel & Venue | E5: 45694 | F5: 45698 | G5: =F5-E5 | H5: 14941.98 | I5: EUR | J5: CC-2871 | K5: GL-6312 | L5: Closed | N5: Cancelled | O5: 45756 | P5: 0 | Q5: Lucas Dupont | R5: Lena Schneider
A6: PO-2025-1005 | B6: EVT-2025-001 | C6: TechEvent Systems | D6: Registration & Tech | E6: 45669 | F6: 45672 | G6: =F6-E6 | H6: 36253.97 | I6: EUR | J6: CC-8231 | K6: GL-6320 | L6: Pending Approval | M6: INV-01005 | N6: Disputed | O6: 45751 | P6: 0 | Q6: Emma Johansson | R6: Marco Bianchi
A7: PO-2025-1006 | B7: EVT-2025-002 | C7: PrintMed Solutions | D7: Print & Production | E7: 45576 | F7: 45582 | G7: =F7-E7 | H7: 48646.86 | I7: EUR | J7: CC-5877 | K7: GL-6330 | L7: Draft | M7: INV-01006 | N7: Overdue | O7: 45653 | P7: 544 | Q7: Carlos Navarro | R7: Isabel Ferreira
A8: PO-2025-1007 | B8: EVT-2025-002 | C8: HealthMarketing Group | D8: Marketing Agency | E8: 45593 | F8: 45597 | G8: =F8-E8 | H8: 19856.1 | I8: EUR | J8: CC-8193 | K8: GL-6330 | L8: Draft | N8: Overdue | O8: 45645 | P8: 552 | Q8: James Wilson | R8: James Wilson
A9: PO-2025-1008 | B9: EVT-2025-002 | C9: Translingua Pro | D9: Translation & Interpretation | E9: 45564 | F9: 45572 | G9: =F9-E9 | H9: 79966.65 | I9: EUR | J9: CC-8015 | K9: GL-6311 | L9: Closed | M9: INV-01008 | N9: Overdue | O9: 45645 | P9: 552 | Q9: Sophie Müller | R9: James Wilson
A10: PO-2025-1009 | B10: EVT-2025-003 | C10: Translingua Pro | D10: Translation & Interpretation | E10: 45676 | F10: 45682 | G10: =F10-E10 | H10: 73453.68 | I10: EUR | J10: CC-1972 | K10: GL-6320 | L10: Approved | M10: INV-01009 | N10: Paid | O10: 45758 | P10: 0 | Q10: Lena Schneider | R10: Isabel Ferreira
A11: PO-2025-1010 | B11: EVT-2025-003 | C11: PrintMed Solutions | D11: Print & Production | E11: 45680 | F11: 45685 | G11: =F11-E11 | H11: 77586.31 | I11: EUR | J11: CC-6302 | K11: GL-6325 | L11: Approved | M11: INV-01010 | N11: Invoiced | O11: 45748 | P11: 0 | Q11: Isabel Ferreira | R11: David O'Brien
A12: PO-2025-1011 | B12: EVT-2025-004 | C12: TechEvent Systems | D12: Registration & Tech | E12: 45731 | F12: 45735 | G12: =F12-E12 | H12: 34108.32 | I12: EUR | J12: CC-3221 | K12: GL-6330 | L12: Sent to Supplier | N12: Paid | O12: 45778 | P12: 0 | Q12: Ana García | R12: Isabel Ferreira
A13: PO-2025-1012 | B13: EVT-2025-005 | C13: AVIAWORLD Travel | D13: Travel & Air | E13: 45863 | F13: 45868 | G13: =F13-E13 | H13: 77674.41 | I13: EUR | J13: CC-3174 | K13: GL-6311 | L13: Pending Approval | M13: INV-01012 | N13: Cancelled | O13: 45948 | P13: 0 | Q13: Thomas Dubois | R13: Lucas Dupont
A14: PO-2025-1013 | B14: EVT-2025-005 | C14: Translingua Pro | D14: Translation & Interpretation | E14: 45864 | F14: 45870 | G14: =F14-E14 | H14: 44322.3 | I14: EUR | J14: CC-7434 | K14: GL-6315 | L14: Pending Approval | M14: INV-01013 | N14: Overdue | O14: 45947 | P14: 250 | Q14: David O'Brien | R14: Maria Kowalski
A15: PO-2025-1014 | B15: EVT-2025-005 | C15: InterCongress PCO | D15: PCO / Event Agency | E15: 45899 | F15: 45908 | G15: =F15-E15 | H15: 40882.46 | I15: EUR | J15: CC-7146 | K15: GL-6315 | L15: Draft | M15: INV-01014 | N15: Approved | O15: 45946 | P15: 0 | Q15: Maria Kowalski | R15: Marco Bianchi
A16: PO-2025-1015 | B16: EVT-2025-005 | C16: PharmaLogix | D16: Logistics & Transport | E16: 45891 | F16: 45898 | G16: =F16-E16 | H16: 74358.48 | I16: EUR | J16: CC-7046 | K16: GL-6315 | L16: Sent to Supplier | M16: INV-01015 | N16: Paid | O16: 45946 | P16: 0 | Q16: Lucas Dupont | R16: David O'Brien
A17: PO-2025-1016 | B17: EVT-2025-005 | C17: Catering Excellence | D17: F&B / Catering | E17: 45923 | F17: 45927 | G17: =F17-E17 | H17: 51141.74 | I17: EUR | J17: CC-8511 | K17: GL-6325 | L17: Cancelled | N17: Invoiced | O17: 45953 | P17: 0 | Q17: Thomas Dubois | R17: Lucas Dupont
A18: PO-2025-1017 | B18: EVT-2025-006 | C18: PrintMed Solutions | D18: Print & Production | E18: 45714 | F18: 45718 | G18: =F18-E18 | H18: 19526.65 | I18: EUR | J18: CC-9756 | K18: GL-6315 | L18: Pending Approval | M18: INV-01017 | N18: Pending | O18: 45798 | P18: 0 | Q18: Emma Johansson | R18: James Wilson
A19: PO-2025-1018 | B19: EVT-2025-007 | C19: Translingua Pro | D19: Translation & Interpretation | E19: 45628 | F19: 45635 | G19: =F19-E19 | H19: 57022.11 | I19: EUR | J19: CC-6289 | K19: GL-6330 | L19: Approved | N19: Paid | O19: 45689 | P19: 0 | Q19: Lucas Dupont | R19: Lena Schneider
A20: PO-2025-1019 | B20: EVT-2025-007 | C20: KOL Connect | D20: Speaker Management | E20: 45630 | F20: 45635 | G20: =F20-E20 | H20: 13282.07 | I20: EUR | J20: CC-8951 | K20: GL-6330 | L20: Approved | M20: INV-01019 | N20: Overdue | O20: 45696 | P20: 501 | Q20: Maria Kowalski | R20: Ana García
A21: PO-2025-1020 | B21: EVT-2025-008 | C21: TechEvent Systems | D21: Registration & Tech | E21: 45949 | F21: 45953 | G21: =F21-E21 | H21: 63620.48 | I21: EUR | J21: CC-8529 | K21: GL-6310 | L21: Draft | N21: Cancelled | O21: 45981 | P21: 0 | Q21: Sophie Müller | R21: Carlos Navarro
A22: PO-2025-1021 | B22: EVT-2025-008 | C22: InterCongress PCO | D22: PCO / Event Agency | E22: 45912 | F22: 45915 | G22: =F22-E22 | H22: 2200.09 | I22: EUR | J22: CC-8009 | K22: GL-6311 | L22: Cancelled | N22: Overdue | O22: 45971 | P22: 226 | Q22: Sophie Müller | R22: Maria Kowalski
A23: PO-2025-1022 | B23: EVT-2025-009 | C23: TechEvent Systems | D23: Registration & Tech | E23: 45821 | F23: 45826 | G23: =F23-E23 | H23: 27930.32 | I23: EUR | J23: CC-5489 | K23: GL-6310 | L23: Cancelled | M23: INV-01022 | N23: Invoiced | O23: 45870 | P23: 0 | Q23: Lucas Dupont | R23: Isabel Ferreira
A24: PO-2025-1023 | B24: EVT-2025-009 | C24: MedAudio AV Solutions | D24: AV & Technology | E24: 45834 | F24: 45842 | G24: =F24-E24 | H24: 56404.88 | I24: EUR | J24: CC-3711 | K24: GL-6310 | L24: Sent to Supplier | N24: Cancelled | O24: 45869 | P24: 0 | Q24: Maria Kowalski | R24: Isabel Ferreira
A25: PO-2025-1024 | B25: EVT-2025-009 | C25: Translingua Pro | D25: Translation & Interpretation | E25: 45796 | F25: 45802 | G25: =F25-E25 | H25: 26817.75 | I25: EUR | J25: CC-8032 | K25: GL-6325 | L25: Draft | M25: INV-01024 | N25: Cancelled | O25: 45872 | P25: 0 | Q25: Thomas Dubois | R25: Marco Bianchi
A26: PO-2025-1025 | B26: EVT-2025-009 | C26: PrintMed Solutions | D26: Print & Production | E26: 45837 | F26: 45843 | G26: =F26-E26 | H26: 53767.73 | I26: EUR | J26: CC-8812 | K26: GL-6310 | L26: Pending Approval | M26: INV-01025 | N26: Paid | O26: 45867 | P26: 0 | Q26: David O'Brien | R26: James Wilson
A27: PO-2025-1026 | B27: EVT-2025-010 | C27: PrintMed Solutions | D27: Print & Production | E27: 45691 | F27: 45701 | G27: =F27-E27 | H27: 9828.44 | I27: EUR | J27: CC-1152 | K27: GL-6310 | L27: Cancelled | M27: INV-01026 | N27: Paid | O27: 45754 | P27: 0 | Q27: Lucas Dupont | R27: Marco Bianchi
A28: PO-2025-1027 | B28: EVT-2025-010 | C28: DigitalPharma Studio | D28: Digital & Web | E28: 45663 | F28: 45672 | G28: =F28-E28 | H28: 33978.33 | I28: EUR | J28: CC-3165 | K28: GL-6315 | L28: Draft | M28: INV-01027 | N28: Pending | O28: 45748 | P28: 0 | Q28: James Wilson | R28: Emma Johansson
A29: PO-2025-1028 | B29: EVT-2025-011 | C29: PharmaLogix | D29: Logistics & Transport | E29: 45941 | F29: 45945 | G29: =F29-E29 | H29: 8264.6 | I29: EUR | J29: CC-2690 | K29: GL-6312 | L29: Approved | M29: INV-01028 | N29: Cancelled | O29: 45976 | P29: 0 | Q29: Isabel Ferreira | R29: Sophie Müller
A30: PO-2025-1029 | B30: EVT-2025-011 | C30: DigitalPharma Studio | D30: Digital & Web | E30: 45910 | F30: 45915 | G30: =F30-E30 | H30: 26699.57 | I30: EUR | J30: CC-3340 | K30: GL-6310 | L30: Closed | M30: INV-01029 | N30: Paid | O30: 45964 | P30: 0 | Q30: David O'Brien | R30: Ana García
A31: PO-2025-1030 | B31: EVT-2025-011 | C31: KOL Connect | D31: Speaker Management | E31: 45910 | F31: 45915 | G31: =F31-E31 | H31: 50161.84 | I31: EUR | J31: CC-8210 | K31: GL-6312 | L31: Cancelled | M31: INV-01030 | N31: Invoiced | O31: 45979 | P31: 0 | Q31: James Wilson | R31: Maria Kowalski
A32: PO-2025-1031 | B32: EVT-2025-012 | C32: MedComm Agency | D32: Medical Communication | E32: 45827 | F32: 45832 | G32: =F32-E32 | H32: 61308.84 | I32: EUR | J32: CC-7745 | K32: GL-6320 | L32: Cancelled | M32: INV-01031 | N32: Paid | O32: 45904 | P32: 0 | Q32: Carlos Navarro | R32: James Wilson
A33: PO-2025-1032 | B33: EVT-2025-013 | C33: HealthMarketing Group | D33: Marketing Agency | E33: 45865 | F33: 45869 | G33: =F33-E33 | H33: 6377.3 | I33: EUR | J33: CC-3293 | K33: GL-6330 | L33: Draft | M33: INV-01032 | N33: Approved | O33: 45900 | P33: 0 | Q33: David O'Brien | R33: Thomas Dubois
A34: PO-2025-1033 | B34: EVT-2025-013 | C34: AVIAWORLD Travel | D34: Travel & Air | E34: 45852 | F34: 45860 | G34: =F34-E34 | H34: 46142.39 | I34: EUR | J34: CC-8035 | K34: GL-6312 | L34: Pending Approval | M34: INV-01033 | N34: Pending | O34: 45906 | P34: 0 | Q34: James Wilson | R34: Isabel Ferreira
A35: PO-2025-1034 | B35: EVT-2025-013 | C35: TechEvent Systems | D35: Registration & Tech | E35: 45833 | F35: 45837 | G35: =F35-E35 | H35: 50337.41 | I35: EUR | J35: CC-5065 | K35: GL-6320 | L35: Closed | M35: INV-01034 | N35: Overdue | O35: 45904 | P35: 293 | Q35: David O'Brien | R35: Thomas Dubois
A36: PO-2025-1035 | B36: EVT-2025-014 | C36: Translingua Pro | D36: Translation & Interpretation | E36: 45888 | F36: 45895 | G36: =F36-E36 | H36: 21915.48 | I36: EUR | J36: CC-1439 | K36: GL-6330 | L36: Cancelled | N36: Paid | O36: 45956 | P36: 0 | Q36: Isabel Ferreira | R36: James Wilson
A37: PO-2025-1036 | B37: EVT-2025-014 | C37: Compliance Expert Ltd | D37: Compliance & Legal | E37: 45879 | F37: 45885 | G37: =F37-E37 | H37: 14322.1 | I37: EUR | J37: CC-7418 | K37: GL-6312 | L37: Cancelled | M37: INV-01036 | N37: Overdue | O37: 45942 | P37: 255 | Q37: Ana García | R37: James Wilson
A38: PO-2025-1037 | B38: EVT-2025-015 | C38: KOL Connect | D38: Speaker Management | E38: 45924 | F38: 45933 | G38: =F38-E38 | H38: 32006.07 | I38: EUR | J38: CC-2847 | K38: GL-6311 | L38: Sent to Supplier | N38: Paid | O38: 45985 | P38: 0 | Q38: Maria Kowalski | R38: David O'Brien
A39: PO-2025-1038 | B39: EVT-2025-015 | C39: Catering Excellence | D39: F&B / Catering | E39: 45944 | F39: 45947 | G39: =F39-E39 | H39: 25078.05 | I39: EUR | J39: CC-6916 | K39: GL-6312 | L39: Pending Approval | M39: INV-01038 | N39: Cancelled | O39: 45978 | P39: 0 | Q39: Emma Johansson | R39: David O'Brien
A40: PO-2025-1039 | B40: EVT-2025-015 | C40: Translingua Pro | D40: Translation & Interpretation | E40: 45923 | F40: 45931 | G40: =F40-E40 | H40: 2631.64 | I40: EUR | J40: CC-9951 | K40: GL-6325 | L40: Pending Approval | M40: INV-01039 | N40: Pending | O40: 45979 | P40: 0 | Q40: Carlos Navarro | R40: Marco Bianchi
...

Sheet Executive Reporting
A1: PHARMACEUTICAL EVENTS – EXECUTIVE FINANCIAL REPORTING | FY 2025
A2: Report Date: 24 June 2026 | Confidential | Finance & PMO
A4: 1. MONTHLY FINANCIAL SUMMARY
A5: Month | B5: # Events | C5: Budget (€) | D5: Committed (€) | E5: Actual (€) | F5: Forecast (€) | G5: Variance (€) | H5: Var % | I5: Budget Absorption % | J5: Status
A6: Jan | B6: =SUMPRODUCT((MONTH('Budget Planning'!$H$2:$H$51)=1)*(YEAR('Budget Planning'!$H$2:$H$51)=2025)*1) | C6: =SUMPRODUCT((MONTH('Budget Planning'!$H$2:$H$51)=1)*(YEAR('Budget Planning'!$H$2:$H$51)=2025)*'Budget Planning'!$J$2:$J$51) | D6: =SUMPRODUCT((MONTH('Budget Planning'!$H$2:$H$51)=1)*(YEAR('Budget Planning'!$H$2:$H$51)=2025)*'Budget Planning'!$N$2:$N$51) | E6: =SUMPRODUCT((MONTH('Budget Planning'!$H$2:$H$51)=1)*(YEAR('Budget Planning'!$H$2:$H$51)=2025)*'Budget Planning'!$O$2:$O$51) | F6: =SUMPRODUCT((MONTH('Budget Planning'!$H$2:$H$51)=1)*(YEAR('Budget Planning'!$H$2:$H$51)=2025)*'Budget Planning'!$M$2:$M$51) | G6: =C6-F6 | H6: =IF(C6=0,0,G6/C6) | I6: =IF(C6=0,0,D6/C6) | J6: =IF(H6<-0.05,"At Risk","On Track")
A7: Feb | B7: =SUMPRODUCT((MONTH('Budget Planning'!$H$2:$H$51)=2)*(YEAR('Budget Planning'!$H$2:$H$51)=2025)*1) | C7: =SUMPRODUCT((MONTH('Budget Planning'!$H$2:$H$51)=2)*(YEAR('Budget Planning'!$H$2:$H$51)=2025)*'Budget Planning'!$J$2:$J$51) | D7: =SUMPRODUCT((MONTH('Budget Planning'!$H$2:$H$51)=2)*(YEAR('Budget Planning'!$H$2:$H$51)=2025)*'Budget Planning'!$N$2:$N$51) | E7: =SUMPRODUCT((MONTH('Budget Planning'!$H$2:$H$51)=2)*(YEAR('Budget Planning'!$H$2:$H$51)=2025)*'Budget Planning'!$O$2:$O$51) | F7: =SUMPRODUCT((MONTH('Budget Planning'!$H$2:$H$51)=2)*(YEAR('Budget Planning'!$H$2:$H$51)=2025)*'Budget Planning'!$M$2:$M$51) | G7: =C7-F7 | H7: =IF(C7=0,0,G7/C7) | I7: =IF(C7=0,0,D7/C7) | J7: =IF(H7<-0.05,"At Risk","On Track")
A8: Mar | B8: =SUMPRODUCT((MONTH('Budget Planning'!$H$2:$H$51)=3)*(YEAR('Budget Planning'!$H$2:$H$51)=2025)*1) | C8: =SUMPRODUCT((MONTH('Budget Planning'!$H$2:$H$51)=3)*(YEAR('Budget Planning'!$H$2:$H$51)=2025)*'Budget Planning'!$J$2:$J$51) | D8: =SUMPRODUCT((MONTH('Budget Planning'!$H$2:$H$51)=3)*(YEAR('Budget Planning'!$H$2:$H$51)=2025)*'Budget Planning'!$N$2:$N$51) | E8: =SUMPRODUCT((MONTH('Budget Planning'!$H$2:$H$51)=3)*(YEAR('Budget Planning'!$H$2:$H$51)=2025)*'Budget Planning'!$O$2:$O$51) | F8: =SUMPRODUCT((MONTH('Budget Planning'!$H$2:$H$51)=3)*(YEAR('Budget Planning'!$H$2:$H$51)=2025)*'Budget Planning'!$M$2:$M$51) | G8: =C8-F8 | H8: =IF(C8=0,0,G8/C8) | I8: =IF(C8=0,0,D8/C8) | J8: =IF(H8<-0.05,"At Risk","On Track")
A9: Apr | B9: =SUMPRODUCT((MONTH('Budget Planning'!$H$2:$H$51)=4)*(YEAR('Budget Planning'!$H$2:$H$51)=2025)*1) | C9: =SUMPRODUCT((MONTH('Budget Planning'!$H$2:$H$51)=4)*(YEAR('Budget Planning'!$H$2:$H$51)=2025)*'Budget Planning'!$J$2:$J$51) | D9: =SUMPRODUCT((MONTH('Budget Planning'!$H$2:$H$51)=4)*(YEAR('Budget Planning'!$H$2:$H$51)=2025)*'Budget Planning'!$N$2:$N$51) | E9: =SUMPRODUCT((MONTH('Budget Planning'!$H$2:$H$51)=4)*(YEAR('Budget Planning'!$H$2:$H$51)=2025)*'Budget Planning'!$O$2:$O$51) | F9: =SUMPRODUCT((MONTH('Budget Planning'!$H$2:$H$51)=4)*(YEAR('Budget Planning'!$H$2:$H$51)=2025)*'Budget Planning'!$M$2:$M$51) | G9: =C9-F9 | H9: =IF(C9=0,0,G9/C9) | I9: =IF(C9=0,0,D9/C9) | J9: =IF(H9<-0.05,"At Risk","On Track")
A10: May | B10: =SUMPRODUCT((MONTH('Budget Planning'!$H$2:$H$51)=5)*(YEAR('Budget Planning'!$H$2:$H$51)=2025)*1) | C10: =SUMPRODUCT((MONTH('Budget Planning'!$H$2:$H$51)=5)*(YEAR('Budget Planning'!$H$2:$H$51)=2025)*'Budget Planning'!$J$2:$J$51) | D10: =SUMPRODUCT((MONTH('Budget Planning'!$H$2:$H$51)=5)*(YEAR('Budget Planning'!$H$2:$H$51)=2025)*'Budget Planning'!$N$2:$N$51) | E10: =SUMPRODUCT((MONTH('Budget Planning'!$H$2:$H$51)=5)*(YEAR('Budget Planning'!$H$2:$H$51)=2025)*'Budget Planning'!$O$2:$O$51) | F10: =SUMPRODUCT((MONTH('Budget Planning'!$H$2:$H$51)=5)*(YEAR('Budget Planning'!$H$2:$H$51)=2025)*'Budget Planning'!$M$2:$M$51) | G10: =C10-F10 | H10: =IF(C10=0,0,G10/C10) | I10: =IF(C10=0,0,D10/C10) | J10: =IF(H10<-0.05,"At Risk","On Track")
A11: Jun | B11: =SUMPRODUCT((MONTH('Budget Planning'!$H$2:$H$51)=6)*(YEAR('Budget Planning'!$H$2:$H$51)=2025)*1) | C11: =SUMPRODUCT((MONTH('Budget Planning'!$H$2:$H$51)=6)*(YEAR('Budget Planning'!$H$2:$H$51)=2025)*'Budget Planning'!$J$2:$J$51) | D11: =SUMPRODUCT((MONTH('Budget Planning'!$H$2:$H$51)=6)*(YEAR('Budget Planning'!$H$2:$H$51)=2025)*'Budget Planning'!$N$2:$N$51) | E11: =SUMPRODUCT((MONTH('Budget Planning'!$H$2:$H$51)=6)*(YEAR('Budget Planning'!$H$2:$H$51)=2025)*'Budget Planning'!$O$2:$O$51) | F11: =SUMPRODUCT((MONTH('Budget Planning'!$H$2:$H$51)=6)*(YEAR('Budget Planning'!$H$2:$H$51)=2025)*'Budget Planning'!$M$2:$M$51) | G11: =C11-F11 | H11: =IF(C11=0,0,G11/C11) | I11: =IF(C11=0,0,D11/C11) | J11: =IF(H11<-0.05,"At Risk","On Track")
A12: Jul | B12: =SUMPRODUCT((MONTH('Budget Planning'!$H$2:$H$51)=7)*(YEAR('Budget Planning'!$H$2:$H$51)=2025)*1) | C12: =SUMPRODUCT((MONTH('Budget Planning'!$H$2:$H$51)=7)*(YEAR('Budget Planning'!$H$2:$H$51)=2025)*'Budget Planning'!$J$2:$J$51) | D12: =SUMPRODUCT((MONTH('Budget Planning'!$H$2:$H$51)=7)*(YEAR('Budget Planning'!$H$2:$H$51)=2025)*'Budget Planning'!$N$2:$N$51) | E12: =SUMPRODUCT((MONTH('Budget Planning'!$H$2:$H$51)=7)*(YEAR('Budget Planning'!$H$2:$H$51)=2025)*'Budget Planning'!$O$2:$O$51) | F12: =SUMPRODUCT((MONTH('Budget Planning'!$H$2:$H$51)=7)*(YEAR('Budget Planning'!$H$2:$H$51)=2025)*'Budget Planning'!$M$2:$M$51) | G12: =C12-F12 | H12: =IF(C12=0,0,G12/C12) | I12: =IF(C12=0,0,D12/C12) | J12: =IF(H12<-0.05,"At Risk","On Track")
A13: Aug | B13: =SUMPRODUCT((MONTH('Budget Planning'!$H$2:$H$51)=8)*(YEAR('Budget Planning'!$H$2:$H$51)=2025)*1) | C13: =SUMPRODUCT((MONTH('Budget Planning'!$H$2:$H$51)=8)*(YEAR('Budget Planning'!$H$2:$H$51)=2025)*'Budget Planning'!$J$2:$J$51) | D13: =SUMPRODUCT((MONTH('Budget Planning'!$H$2:$H$51)=8)*(YEAR('Budget Planning'!$H$2:$H$51)=2025)*'Budget Planning'!$N$2:$N$51) | E13: =SUMPRODUCT((MONTH('Budget Planning'!$H$2:$H$51)=8)*(YEAR('Budget Planning'!$H$2:$H$51)=2025)*'Budget Planning'!$O$2:$O$51) | F13: =SUMPRODUCT((MONTH('Budget Planning'!$H$2:$H$51)=8)*(YEAR('Budget Planning'!$H$2:$H$51)=2025)*'Budget Planning'!$M$2:$M$51) | G13: =C13-F13 | H13: =IF(C13=0,0,G13/C13) | I13: =IF(C13=0,0,D13/C13) | J13: =IF(H13<-0.05,"At Risk","On Track")
